File: Done/python-workspace/python-mathematical/prob_3_4_00000000_홍길동.csv
Displacement(m),Load(kN),Stress(kPa),Strain
1e-05,2.3,1171.3806248551687,0.0001
1e-05,2.6,1324.1694020101909,0.0001
1e-05,2.9,1476.9581791652126,0.0001
1e-05,3.2,1629.7469563202349,0.0001
1e-05,3.5,1782.5357334752568,0.0001
1e-05,3.8,1935.3245106302786,0.0001
1e-05,4.1,2088.1132877853006,0.0001
1e-05,4.4,2240.902064940323,0.0001
2e-05,4.7,2393.690842095345,0.0002
2e-05,5.0,2546.479619250367,0.0002
2e-05,5.3,2699.2683964053886,0.0002
2e-05,5.6,2852.057173560411,0.0002
2e-05,6.0,3055.7755431004402,0.0002
2e-05,6.3,3208.564320255462,0.0002
2.9999999999999997e-05,6.6,3361.3530974104838,0.0003
2.9999999999999997e-05,7.0,3565.0714669505137,0.0003
2.9999999999999997e-05,7.4,3768.789836490543,0.0003
2.9999999999999997e-05,7.7,3921.578613645565,0.0003
2.9999999999999997e-05,8.0,4074.3673908005867,0.0003
2.9999999999999997e-05,8.3,4227.156167955609,0.0003
2.9999999999999997e-05,8.7,4430.874537495638,0.0003
2.9999999999999997e-05,9.0,4583.66331465066,0.0003
2.9999999999999997e-05,9.3,4736.452091805682,0.0003
4e-05,9.5,4838.311276575697,0.0004
4e-05,9.8,4991.100053730719,0.0004
4e-05,10.1,5143.88883088574,0.0004
4e-05,10.4,5296.6776080407635,0.0004
4e-05,10.7,5449.466385195785,0.0004
4e-05,11.0,5602.255162350807,0.0004
4e-05,11.3,5755.043939505829,0.0004
4e-05,11.6,5907.832716660851,0.0004
5e-05,12.0,6111.5510862008805,0.0005
5e-05,12.4,6315.2694557409095,0.0005
5e-05,12.8,6518.987825280939,0.0005
5e-05,13.1,6671.776602435961,0.0005
5e-05,13.4,6824.565379590983,0.0005
5e-05,13.7,6977.354156746004,0.0005
5e-05,14.1,7181.072526286034,0.0005
5e-05,14.4,7333.861303441056,0.0005
5.9999999999999995e-05,14.7,7486.650080596078,0.0006
5.9999999999999995e-05,15.0,7639.4388577511,0.0006
5.9999999999999995e-05,15.3,7792.227634906123,0.0006
5.9999999999999995e-05,15.6,7945.016412061144,0.0006
5.9999999999999995e-05,15.9,8097.805189216167,0.0006
5.9999999999999995e-05,16.2,8250.593966371189,0.0006
5.9999999999999995e-05,16.5,8403.38274352621,0.0006
5.9999999999999995e-05,16.9,8607.10111306624,0.0006
5.9999999999999995e-05,17.3,8810.81948260627,0.0006
7.000000000000001e-05,17.8,9065.467444531307,0.0007
7.000000000000001e-05,18.1,9218.256221686328,0.0007
7.000000000000001e-05,18.5,9421.974591226357,0.0007
7.000000000000001e-05,18.9,9625.692960766386,0.0007
7.000000000000001e-05,19.3,9829.411330306417,0.0007
7.000000000000001e-05,19.7,10033.129699846444,0.0007
7.000000000000001e-05,20.1,10236.848069386475,0.0007
7.000000000000001e-05,20.4,10389.636846541496,0.0007
8e-05,20.9,10644.284808466533,0.0008
8e-05,21.2,10797.073585621554,0.0008
8e-05,21.6,11000.791955161585,0.0008
8e-05,22.0,11204.510324701614,0.0008
8e-05,22.5,11459.15828662665,0.0008
8e-05,23.0,11713.806248551688,0.0008
8e-05,23.4,11917.524618091717,0.0008
8e-05,23.8,12121.242987631746,0.0008
8.999999999999999e-05,24.3,12375.890949556782,0.0008999999999999999
8.999999999999999e-05,24.7,12579.609319096811,0.0008999999999999999
8.999999999999999e-05,25.1,12783.327688636842,0.0008999999999999999
8.999999999999999e-05,25.6,13037.975650561879,0.0008999999999999999
8.999999999999999e-05,25.9,13190.764427716898,0.0008999999999999999
8.999999999999999e-05,26.4,13445.412389641935,0.0008999999999999999
8.999999999999999e-05,26.8,13649.130759181966,0.0008999999999999999
8.999999999999999e-05,27.2,13852.849128721995,0.0008999999999999999
8.999999999999999e-05,27.6,14056.567498262026,0.0008999999999999999
0.0001,28.1,14311.215460187062,0.001
0.0001,28.5,14514.93382972709,0.001
0.0001,28.9,14718.652199267119,0.001
0.0001,29.3,14922.37056880715,0.001
0.0001,29.7,15126.088938347179,0.001
0.0001,30.2,15380.736900272215,0.001
0.0001,30.7,15635.384862197252,0.001
0.00011,31.2,15890.032824122289,0.0011
0.00011,31.7,16144.680786047325,0.0011
0.00011,32.2,16399.328747972362,0.0011
0.00011,32.7,16653.9767098974,0.0011
0.00011,33.3,16959.55426420744,0.0011
0.00011,33.9,17265.131818517486,0.0011
0.00011,34.5,17570.709372827532,0.0011
0.00011,34.9,17774.42774236756,0.0011
0.00011,35.4,18029.075704292594,0.0011
0.00011999999999999999,35.8,18232.794073832625,0.0012
0.00011999999999999999,36.5,18589.30122052768,0.0012
0.00011999999999999999,36.9,18793.019590067706,0.0012
0.00011999999999999999,37.4,19047.66755199274,0.0012
0.00011999999999999999,37.7,19200.456329147768,0.0012
0.00011999999999999999,38.2,19455.104291072803,0.0012
0.00011999999999999999,38.5,19607.893068227822,0.0012
0.00011999999999999999,38.8,19760.681845382845,0.0012
0.00011999999999999999,39.2,19964.400214922876,0.0012
0.00013000000000000002,39.8,20269.97776923292,0.0013000000000000002
0.00013000000000000002,40.2,20473.69613877295,0.0013000000000000002
0.00013000000000000002,40.6,20677.41450831298,0.0013000000000000002
0.00013000000000000002,41.0,20881.132877853008,0.0013000000000000002
0.00013000000000000002,41.4,21084.851247393035,0.0013000000000000002
0.00013000000000000002,41.9,21339.499209318074,0.0013000000000000002
0.00013000000000000002,42.3,21543.2175788581,0.0013000000000000002
0.00013000000000000002,42.6,21696.006356013124,0.0013000000000000002
0.00013000000000000002,43.0,21899.724725553155,0.0013000000000000002
0.00013000000000000002,43.4,22103.443095093182,0.0013000000000000002
0.00014000000000000001,43.8,22307.161464633213,0.0014
0.00014000000000000001,44.1,22459.950241788236,0.0014
0.00014000000000000001,44.5,22663.668611328263,0.0014
0.00014000000000000001,44.9,22867.386980868294,0.0014
0.00014000000000000001,45.3,23071.10535040832,0.0014
0.00014000000000000001,45.8,23325.75331233336,0.0014
0.00014000000000000001,46.4,23631.330866643402,0.0014
0.00015,46.9,23885.97882856844,0.0014999999999999998
0.00015,47.4,24140.626790493476,0.0014999999999999998
0.00015,47.9,24395.274752418514,0.0014999999999999998
0.00015,48.3,24598.99312195854,0.0014999999999999998
0.00015,48.8,24853.64108388358,0.0014999999999999998
0.00015,49.1,25006.429861038603,0.0014999999999999998
0.00015,49.6,25261.077822963638,0.0014999999999999998
0.00015,50.0,25464.79619250367,0.0014999999999999998
0.00015,50.6,25770.37374681371,0.0014999999999999998
0.00015,51.0,25974.092116353742,0.0014999999999999998
0.00015,51.6,26279.669670663785,0.0014999999999999998
0.00016,52.0,26483.388040203816,0.0016
0.00016,52.4,26687.106409743843,0.0016
0.00016,53.0,26992.68396405389,0.0016
0.00016,53.5,27247.331925978924,0.0016
0.00016,54.0,27501.979887903963,0.0016
0.00016,54.5,27756.627849828998,0.0016
0.00016,54.9,27960.346219369025,0.0016
0.00016,55.3,28164.064588909056,0.0016
0.00017,55.9,28469.6421432191,0.0017000000000000001
0.00017,56.4,28724.290105144137,0.0017000000000000001
0.00017,56.9,28978.93806706917,0.0017000000000000001
0.00017,57.4,29233.58602899421,0.0017000000000000001
0.00017,57.8,29437.304398534237,0.0017000000000000001
0.00017,58.3,29691.952360459276,0.0017000000000000001
0.00017,58.9,29997.52991476932,0.0017000000000000001
0.00017999999999999998,59.3,30201.24828430935,0.0017999999999999997
0.00017999999999999998,59.8,30455.896246234384,0.0017999999999999997
0.00017999999999999998,60.3,30710.544208159423,0.0017999999999999997
0.00017999999999999998,60.8,30965.192170084458,0.0017999999999999997
0.00017999999999999998,61.3,31219.840132009496,0.0017999999999999997
0.00017999999999999998,61.8,31474.48809393453,0.0017999999999999997
0.00017999999999999998,62.3,31729.13605585957,0.0017999999999999997
0.00017999999999999998,62.8,31983.784017784605,0.0017999999999999997
0.00017999999999999998,63.2,32187.50238732464,0.0017999999999999997
0.00019,63.8,32493.079941634678,0.0019
0.00019,64.5,32849.58708832973,0.0019
0.00019,65.0,33104.23505025477,0.0019
0.00019,65.5,33358.8830121798,0.0019
0.00019,65.9,33562.60138171984,0.0019
0.00019,66.3,33766.31975125986,0.0019
0.00019,66.7,33970.038120799894,0.0019
0.00019,67.2,34224.68608272493,0.0019
0.0002,67.8,34530.26363703497,0.002
0.0002,68.3,34784.91159896001,0.002
0.0002,68.8,35039.55956088504,0.002
0.0002,69.2,35243.27793042508,0.002
0.0002,69.8,35548.85548473512,0.002
0.0002,70.2,35752.57385427515,0.002
0.0002,70.6,35956.29222381517,0.002
0.0002,71.0,36160.01059335521,0.002
0.0002,71.5,36414.65855528024,0.002
0.00020999999999999998,72.1,36720.23610959029,0.0021
0.00020999999999999998,72.7,37025.813663900335,0.0021
0.00020999999999999998,73.2,37280.46162582537,0.0021
0.00020999999999999998,73.8,37586.03918013541,0.0021
0.00020999999999999998,74.1,37738.827957290436,0.0021
0.00020999999999999998,74.5,37942.54632683047,0.0021
0.00020999999999999998,74.8,38095.33510398548,0.0021
0.00020999999999999998,75.2,38299.05347352552,0.0021
0.00022,75.7,38553.70143545055,0.0022
0.00022,76.1,38757.41980499058,0.0022
0.00022,76.6,39012.067766915614,0.0022
0.00022,77.1,39266.71572884065,0.0022
0.00022,77.4,39419.50450599568,0.0022
0.00022,78.0,39725.08206030572,0.0022
0.00022,78.4,39928.80042984575,0.0022
0.00022,78.9,40183.44839177079,0.0022
0.00022,79.3,40387.166761310815,0.0022
0.00023,79.8,40641.81472323585,0.0023
0.00023,80.2,40845.533092775884,0.0023
0.00023,80.7,41100.18105470092,0.0023
0.00023,81.3,41405.75860901096,0.0023
0.00023,81.7,41609.47697855099,0.0023
0.00023,82.2,41864.12494047603,0.0023
0.00023,82.7,42118.77290240107,0.0023
0.00023,83.1,42322.49127194109,0.0023
0.00023999999999999998,83.7,42628.06882625114,0.0024
0.00023999999999999998,84.1,42831.78719579116,0.0024
0.00023999999999999998,84.6,43086.4351577162,0.0024
0.00023999999999999998,85.0,43290.15352725623,0.0024
0.00023999999999999998,85.5,43544.80148918127,0.0024
0.00023999999999999998,85.9,43748.5198587213,0.0024
0.00023999999999999998,86.5,44054.09741303135,0.0024
0.00023999999999999998,86.9,44257.81578257138,0.0024
0.00025,87.7,44665.25252165143,0.0025
0.00025,88.3,44970.83007596147,0.0025
0.00025,88.8,45225.47803788651,0.0025
0.00025,89.5,45581.985184581565,0.0025
0.00025,90.0,45836.6331465066,0.0025
0.00025,90.4,46040.351516046634,0.0025
0.00025,90.9,46294.99947797167,0.0025
0.00026000000000000003,91.4,46549.647439896704,0.0026000000000000003
0.00026000000000000003,92.0,46855.22499420675,0.0026000000000000003
0.00026000000000000003,92.4,47058.94336374678,0.0026000000000000003
0.00026000000000000003,92.9,47313.59132567182,0.0026000000000000003
0.00026000000000000003,93.5,47619.16887998186,0.0026000000000000003
0.00026000000000000003,94.0,47873.8168419069,0.0026000000000000003
0.00026000000000000003,94.5,48128.464803831936,0.0026000000000000003
0.00027,95.3,48535.90154291199,0.0026999999999999997
0.00027,95.8,48790.54950483703,0.0026999999999999997
0.00027,96.3,49045.19746676206,0.0026999999999999997
0.00027,96.8,49299.8454286871,0.0026999999999999997
0.00027,97.3,49554.49339061214,0.0026999999999999997
0.00027,97.9,49860.07094492218,0.0026999999999999997
0.00027,98.3,50063.78931446221,0.0026999999999999997
0.00027,98.9,50369.36686877226,0.0026999999999999997
0.00027,99.3,50573.085238312284,0.0026999999999999997
0.00028000000000000003,99.9,50878.66279262233,0.0028
0.00028000000000000003,100.5,51184.24034693237,0.0028
0.00028000000000000003,101.0,51438.88830885741,0.0028
0.00028000000000000003,101.4,51642.60667839744,0.0028
0.00028000000000000003,101.9,51897.25464032248,0.0028
0.00028000000000000003,102.4,52151.902602247515,0.0028
0.00028000000000000003,102.8,52355.62097178754,0.0028
0.00029,103.5,52712.12811848259,0.0029
0.00029,104.0,52966.77608040763,0.0029
0.00029,104.5,53221.42404233266,0.0029
0.00029,104.9,53425.1424118727,0.0029
0.00029,105.4,53679.79037379773,0.0029
0.00029,105.9,53934.43833572277,0.0029
0.00029,106.3,54138.156705262794,0.0029
0.00029,106.8,54392.80466718783,0.0029
0.00029,107.2,54596.523036727864,0.0029
0.00029,107.6,54800.24140626789,0.0029
0.0003,108.0,55003.959775807925,0.0029999999999999996
0.0003,108.5,55258.60773773296,0.0029999999999999996
0.0003,109.1,55564.185292043,0.0029999999999999996
0.0003,109.7,55869.76284635305,0.0029999999999999996
0.0003,110.0,56022.55162350807,0.0029999999999999996
0.0003,110.4,56226.2699930481,0.0029999999999999996
0.0003,110.8,56429.98836258813,0.0029999999999999996
0.0003,111.3,56684.636324513165,0.0029999999999999996
0.00031,112.1,57092.07306359322,0.0031
0.00031,112.6,57346.72102551826,0.0031
0.00031,113.1,57601.3689874433,0.0031
0.00031,113.5,57805.08735698333,0.0031
0.00031,114.2,58161.59450367838,0.0031
0.00031,114.7,58416.24246560341,0.0031
0.00031,115.2,58670.89042752845,0.0031
0.00031,115.8,58976.46798183849,0.0031
0.00032,116.2,59180.18635137853,0.0032
0.00032,116.8,59485.76390568857,0.0032
0.00032,117.4,59791.34145999861,0.0032
0.00032,117.9,60045.98942192365,0.0032
0.00032,118.2,60198.778199078675,0.0032
0.00032,118.5,60351.56697623369,0.0032
0.00032,118.8,60504.355753388714,0.0032
0.00032,119.3,60759.00371531375,0.0032
0.00032,119.9,61064.5812696238,0.0032
0.00033,120.4,61319.22923154884,0.0033
0.00033,120.9,61573.87719347387,0.0033
0.00033,121.4,61828.52515539891,0.0033
0.00033,121.9,62083.173117323946,0.0033
0.00033,122.3,62286.89148686397,0.0033
0.00033,122.8,62541.53944878901,0.0033
0.00033,123.2,62745.25781832904,0.0033
0.00033,123.7,62999.90578025408,0.0033
0.00034,124.2,63254.55374217911,0.0034000000000000002
0.00034,124.6,63458.27211171914,0.0034000000000000002
0.00034,125.2,63763.849666029186,0.0034000000000000002
0.00034,125.7,64018.497627954224,0.0034000000000000002
0.00034,126.1,64222.21599749425,0.0034000000000000002
0.00034,126.5,64425.93436703428,0.0034000000000000002
0.00034,126.9,64629.65273657431,0.0034000000000000002
0.00034,127.3,64833.37110611433,0.0034000000000000002
0.00034,127.8,65088.01906803937,0.0034000000000000002
0.00035,128.7,65546.38539950443,0.0034999999999999996
0.00035,129.4,65902.8925461995,0.0034999999999999996
0.00035,130.0,66208.47010050954,0.0034999999999999996
0.00035,130.6,66514.04765481957,0.0034999999999999996
0.00035,131.2,66819.62520912962,0.0034999999999999996
0.00035,131.7,67074.27317105465,0.0034999999999999996
0.00035,132.1,67277.99154059468,0.0034999999999999996
0.00035999999999999997,132.7,67583.56909490473,0.0035999999999999995
0.00035999999999999997,133.3,67889.14664921479,0.0035999999999999995
0.00035999999999999997,134.1,68296.58338829484,0.0035999999999999995
0.00035999999999999997,134.6,68551.23135021987,0.0035999999999999995
0.00035999999999999997,135.1,68805.87931214491,0.0035999999999999995
0.00035999999999999997,135.6,69060.52727406994,0.0035999999999999995
0.00035999999999999997,136.0,69264.24564360997,0.0035999999999999995
0.00037,136.5,69518.893605535,0.0036999999999999997
0.00037,137.1,69824.47115984505,0.0036999999999999997
0.00037,137.6,70079.11912177008,0.0036999999999999997
0.00037,138.2,70384.69667608013,0.0036999999999999997
0.00037,138.7,70639.34463800518,0.0036999999999999997
0.00037,139.3,70944.92219231522,0.0036999999999999997
0.00037,139.7,71148.64056185524,0.0036999999999999997
0.00037,140.1,71352.35893139527,0.0036999999999999997
0.00038,140.7,71657.93648570532,0.0038
0.00038,141.2,71912.58444763035,0.0038
0.00038,141.8,72218.1620019404,0.0038
0.00038,142.4,72523.73955625045,0.0038
0.00038,142.8,72727.45792579048,0.0038
0.00038,143.2,72931.1762953305,0.0038
0.00038,143.7,73185.82425725553,0.0038
0.00038,144.1,73389.54262679556,0.0038
0.00039,144.7,73695.12018110561,0.0039
0.00039,145.3,74000.69773541567,0.0039
0.00039,145.9,74306.2752897257,0.0039
0.00039,146.3,74509.99365926573,0.0039
0.00039,146.7,74713.71202880575,0.0039
0.00039,147.1,74917.4303983458,0.0039
0.00039,147.6,75172.07836027083,0.0039
0.00039,148.2,75477.65591458087,0.0039
0.0004,148.7,75732.3038765059,0.004
0.0004,149.1,75936.02224604593,0.004
0.0004,149.6,76190.67020797096,0.004
0.0004,150.0,76394.38857751101,0.004
0.0004,150.5,76649.03653943604,0.004
0.0004,150.9,76852.75490897607,0.004
0.0004,151.3,77056.4732785161,0.004
0.0004,151.7,77260.19164805612,0.004
0.0004,152.1,77463.91001759615,0.004
0.00041,152.7,77769.4875719062,0.0040999999999999995
0.00041,153.2,78024.13553383123,0.0040999999999999995
0.00041,153.6,78227.85390337126,0.0040999999999999995
0.00041,154.0,78431.57227291129,0.0040999999999999995
0.00041,154.3,78584.36105006632,0.0040999999999999995
0.00041,154.6,78737.14982722134,0.0040999999999999995
0.00041,155.1,78991.79778914638,0.0040999999999999995
0.00041,155.5,79195.51615868641,0.0040999999999999995
0.00041999999999999996,156.0,79450.16412061144,0.0042
0.00041999999999999996,156.5,79704.81208253647,0.0042
0.00041999999999999996,156.8,79857.6008596915,0.0042
0.00041999999999999996,157.3,80112.24882161655,0.0042
0.00041999999999999996,157.6,80265.03759877155,0.0042
0.00041999999999999996,158.0,80468.75596831158,0.0042
0.00041999999999999996,158.4,80672.47433785163,0.0042
0.00041999999999999996,158.8,80876.19270739166,0.0042
0.00043,159.2,81079.91107693168,0.0043
0.00043,159.6,81283.6294464717,0.0043
0.00043,160.0,81487.34781601174,0.0043
0.00043,160.3,81640.13659316677,0.0043
0.00043,160.7,81843.85496270678,0.0043
0.00043,161.0,81996.64373986181,0.0043
0.00043,161.4,82200.36210940185,0.0043
0.00043,161.9,82455.01007132688,0.0043
0.00044,162.5,82760.58762563692,0.0044
0.00044,163.0,83015.23558756195,0.0044
0.00044,163.5,83269.883549487,0.0044
0.00044,163.9,83473.60191902703,0.0044
0.00044,164.5,83779.17947333706,0.0044
0.00044,164.9,83982.8978428771,0.0044
0.00044,165.3,84186.61621241712,0.0044
0.00044,165.8,84441.26417434217,0.0044
0.00045,166.3,84695.9121362672,0.0045
0.00045,166.7,84899.63050580722,0.0045
0.00045,167.4,85256.13765250228,0.0045
0.00045,167.8,85459.85602204231,0.0045
0.00045,168.2,85663.57439158233,0.0045
0.00045,168.5,85816.36316873736,0.0045
0.00045,168.8,85969.15194589239,0.0045
0.00045,169.1,86121.9407230474,0.0045
0.00045,169.6,86376.58868497243,0.0045
0.00046,170.1,86631.23664689748,0.0046
0.00046,170.5,86834.95501643751,0.0046
0.00046,171.0,87089.60297836254,0.0046
0.00046,171.4,87293.32134790257,0.0046
0.00046,171.8,87497.0397174426,0.0046
0.00046,172.1,87649.82849459762,0.0046
0.00046,172.5,87853.54686413765,0.0046
0.00047,172.9,88057.26523367768,0.004699999999999999
0.00047,173.3,88260.98360321771,0.004699999999999999
0.00047,173.7,88464.70197275774,0.004699999999999999
0.00047,174.2,88719.34993468277,0.004699999999999999
0.00047,174.6,88923.0683042228,0.004699999999999999
0.00047,175.1,89177.71626614784,0.004699999999999999
0.00047,175.6,89432.36422807288,0.004699999999999999
0.00047999999999999996,175.9,89585.15300522791,0.0048
0.00047999999999999996,176.4,89839.80096715294,0.0048
0.00047999999999999996,176.9,90094.44892907797,0.0048
0.00047999999999999996,177.3,90298.167298618,0.0048
0.00047999999999999996,177.7,90501.88566815804,0.0048
0.00047999999999999996,178.2,90756.53363008307,0.0048
0.00047999999999999996,178.6,90960.2519996231,0.0048
0.00047999999999999996,179.0,91163.97036916313,0.0048
0.00049,179.6,91469.54792347318,0.0049
0.00049,180.0,91673.2662930132,0.0049
0.00049,180.4,91876.98466255324,0.0049
0.00049,181.0,92182.56221686328,0.0049
0.00049,181.3,92335.3509940183,0.0049
0.00049,181.6,92488.13977117332,0.0049
0.00049,181.9,92640.92854832835,0.0049
0.0005,182.2,92793.71732548336,0.005
0.0005,182.6,92997.43569502339,0.005
0.0005,183.1,93252.08365694842,0.005
0.0005,183.5,93455.80202648845,0.005
0.0005,183.9,93659.5203960285,0.005
0.0005,184.2,93812.3091731835,0.005
0.0005,184.6,94016.02754272353,0.005
0.00051,184.9,94168.81631987856,0.0051
0.00051,185.3,94372.5346894186,0.0051
0.00051,185.6,94525.32346657361,0.0051
0.00051,185.9,94678.11224372864,0.0051
0.00051,186.2,94830.90102088366,0.0051
0.00051,186.5,94983.68979803869,0.0051
0.00051,186.8,95136.4785751937,0.0051
0.00051,187.1,95289.26735234872,0.0051
0.0005200000000000001,187.7,95594.84490665876,0.005200000000000001
0.0005200000000000001,188.1,95798.5632761988,0.005200000000000001
0.0005200000000000001,188.6,96053.21123812383,0.005200000000000001
0.0005200000000000001,189.1,96307.85920004887,0.005200000000000001
0.0005200000000000001,189.5,96511.5775695889,0.005200000000000001
0.0005200000000000001,189.9,96715.29593912893,0.005200000000000001
0.0005200000000000001,190.2,96868.08471628395,0.005200000000000001
0.00053,190.7,97122.73267820898,0.005299999999999999
0.00053,191.1,97326.45104774901,0.005299999999999999
0.00053,191.5,97530.16941728904,0.005299999999999999
0.00053,191.8,97682.95819444407,0.005299999999999999
0.00053,192.2,97886.67656398409,0.005299999999999999
0.00053,192.5,98039.46534113912,0.005299999999999999
0.00053,192.9,98243.18371067915,0.005299999999999999
0.00054,193.2,98395.97248783417,0.005399999999999999
0.00054,193.7,98650.6204497592,0.005399999999999999
0.00054,194.1,98854.33881929923,0.005399999999999999
0.00054,194.5,99058.05718883927,0.005399999999999999
0.00054,194.8,99210.84596599429,0.005399999999999999
0.00054,195.1,99363.6347431493,0.005399999999999999
0.00055,195.4,99516.42352030434,0.0055
0.00055,195.7,99669.21229745935,0.0055
0.00055,196.0,99822.00107461438,0.0055
0.00055,196.3,99974.78985176941,0.0055
0.00055,196.6,100127.57862892441,0.0055
0.00055,196.9,100280.36740607944,0.0055
0.00055,197.2,100433.15618323446,0.0055
0.00055,197.6,100636.87455277449,0.0055
0.0005600000000000001,198.1,100891.52251469952,0.0056
0.0005600000000000001,198.5,101095.24088423957,0.0056
0.0005600000000000001,198.9,101298.9592537796,0.0056
0.0005600000000000001,199.2,101451.7480309346,0.0056
0.0005600000000000001,199.5,101604.53680808963,0.0056
0.0005600000000000001,199.9,101808.25517762966,0.0056
0.00057,200.3,102011.9735471697,0.005699999999999999
0.00057,200.6,102164.7623243247,0.005699999999999999
0.00057,201.0,102368.48069386474,0.005699999999999999
0.00057,201.4,102572.19906340478,0.005699999999999999
0.00057,201.7,102724.98784055978,0.005699999999999999
0.00057,202.0,102877.77661771482,0.005699999999999999
0.00057,202.3,103030.56539486985,0.005699999999999999
0.00058,202.6,103183.35417202486,0.0058
0.00058,202.9,103336.14294917989,0.0058
0.00058,203.2,103488.9317263349,0.0058
0.00058,203.5,103641.72050348992,0.0058
0.00058,203.8,103794.50928064495,0.0058
0.0005899999999999999,204.1,103947.29805779997,0.005899999999999999
0.0005899999999999999,204.4,104100.086834955,0.005899999999999999
0.0005899999999999999,204.8,104303.80520449503,0.005899999999999999
0.0005899999999999999,205.2,104507.52357403505,0.005899999999999999
0.0005899999999999999,205.5,104660.31235119008,0.005899999999999999
0.0005899999999999999,206.0,104914.96031311511,0.005899999999999999
0.0006,206.5,105169.60827504015,0.005999999999999999
0.0006,206.8,105322.39705219517,0.005999999999999999
0.0006,207.1,105475.18582935019,0.005999999999999999
0.0006,207.5,105678.90419889022,0.005999999999999999
0.0006,207.8,105831.69297604525,0.005999999999999999
0.00061,208.1,105984.48175320026,0.0060999999999999995
0.00061,208.6,106239.1297151253,0.0060999999999999995
0.00061,208.9,106391.91849228033,0.0060999999999999995
0.00061,209.3,106595.63686182036,0.0060999999999999995
0.00061,209.6,106748.42563897537,0.0060999999999999995
0.00061,209.9,106901.2144161304,0.0060999999999999995
0.00062,210.2,107054.00319328542,0.0062
0.00062,210.7,107308.65115521045,0.0062
0.00062,211.1,107512.36952475048,0.0062
0.00062,211.6,107767.01748667553,0.0062
0.00063,212.0,107970.73585621556,0.0063
0.00063,212.3,108123.52463337057,0.0063
0.00063,212.6,108276.31341052559,0.0063
0.00063,212.9,108429.10218768062,0.0063
0.00063,213.2,108581.89096483563,0.0063
0.00064,213.4,108683.75014960565,0.0064
0.00064,213.7,108836.53892676067,0.0064
0.00064,214.0,108989.3277039157,0.0064
0.00065,214.2,109091.18688868571,0.0065
0.00065,214.5,109243.97566584073,0.0065
0.00065,214.8,109396.76444299576,0.0065
0.00065,215.1,109549.55322015077,0.0065
0.00066,215.3,109651.4124049208,0.0066
0.00066,215.6,109804.2011820758,0.0066
0.00066,215.9,109956.98995923084,0.0066
0.00066,216.2,110109.77873638585,0.0066
0.00066,216.5,110262.56751354088,0.0066
0.00067,216.8,110415.35629069591,0.0067
0.00067,217.1,110568.14506785093,0.0067
0.00067,217.4,110720.93384500594,0.0067
0.00067,217.7,110873.72262216096,0.0067
0.00068,217.9,110975.58180693099,0.0068000000000000005
0.00068,218.2,111128.370584086,0.0068000000000000005
0.00068,218.5,111281.15936124102,0.0068000000000000005
0.00069,218.8,111433.94813839605,0.006899999999999999
0.00069,219.1,111586.73691555107,0.006899999999999999
0.00069,219.4,111739.5256927061,0.006899999999999999
0.0007,219.6,111841.3848774761,0.006999999999999999
0.0007099999999999999,219.8,111943.24406224613,0.007099999999999999
0.0007099999999999999,220.1,112096.03283940114,0.007099999999999999
0.0007199999999999999,219.9,111994.17365463113,0.007199999999999999
0.00073,220.1,112096.03283940114,0.007299999999999999
0.00073,220.2,112146.96243178615,0.007299999999999999
0.00074,220.3,112197.89202417116,0.0073999999999999995
0.00074,220.4,112248.82161655618,0.0073999999999999995
0.00074,220.1,112096.03283940114,0.0073999999999999995
0.00075,219.9,111994.17365463113,0.0075
0.00075,219.6,111841.3848774761,0.0075
0.00076,219.4,111739.5256927061,0.0076
0.00076,219.1,111586.73691555107,0.0076
0.00076,218.8,111433.94813839605,0.0076
0.00076,218.5,111281.15936124102,0.0076
0.0007700000000000001,218.2,111128.370584086,0.0077
0.0007700000000000001,217.9,110975.58180693099,0.0077
0.0007700000000000001,217.6,110822.79302977596,0.0077
0.0007700000000000001,217.3,110670.00425262094,0.0077
0.00078,217.0,110517.21547546591,0.0078
0.00078,216.7,110364.42669831088,0.0078
0.00079,216.4,110211.63792115588,0.007899999999999999
0.00079,216.1,110058.84914400085,0.007899999999999999
0.00079,215.7,109855.13077446082,0.007899999999999999
0.00079,215.3,109651.4124049208,0.007899999999999999
0.00079,214.9,109447.69403538077,0.007899999999999999
0.00079,214.6,109294.90525822574,0.007899999999999999
0.00079,214.2,109091.18688868571,0.007899999999999999
0.0008,213.8,108887.4685191457,0.008
0.0008,213.2,108581.89096483563,0.008
0.0008,212.7,108327.2430029106,0.008
0.0008,212.2,108072.59504098556,0.008
0.0008,211.7,107817.94707906053,0.008
0.0008,211.3,107614.22870952051,0.008
0.0008100000000000001,210.8,107359.58074759546,0.0081
0.0008100000000000001,210.4,107155.86237805543,0.0081
0.0008100000000000001,210.0,106952.1440085154,0.0081
0.0008100000000000001,209.6,106748.42563897537,0.0081
0.0008100000000000001,209.1,106493.77767705034,0.0081
0.0008100000000000001,208.7,106290.05930751031,0.0081
0.00082,208.3,106086.34093797028,0.008199999999999999
0.00082,207.9,105882.62256843025,0.008199999999999999
0.00082,207.4,105627.97460650522,0.008199999999999999
0.00082,207.1,105475.18582935019,0.008199999999999999
0.00082,206.7,105271.46745981016,0.008199999999999999
0.00082,206.3,105067.74909027014,0.008199999999999999
0.00082,205.9,104864.03072073011,0.008199999999999999
0.00083,205.5,104660.31235119008,0.0083
0.00083,205.0,104405.66438926503,0.0083
0.00083,204.6,104201.946019725,0.0083
0.00083,204.1,103947.29805779997,0.0083
0.00083,203.6,103692.65009587494,0.0083
0.00083,203.2,103488.9317263349,0.0083
0.00083,202.8,103285.21335679488,0.0083
0.00083,202.4,103081.49498725485,0.0083
0.0008399999999999999,201.9,102826.84702532981,0.0084
0.0008399999999999999,201.5,102623.12865578978,0.0084
0.0008399999999999999,201.2,102470.33987863475,0.0084
0.0008399999999999999,200.9,102317.55110147974,0.0084
0.0008399999999999999,200.5,102113.8327319397,0.0084
0.0008399999999999999,200.1,101910.11436239968,0.0084
0.00085,199.7,101706.39599285965,0.008499999999999999
0.00085,199.3,101502.67762331963,0.008499999999999999
0.00085,198.8,101248.02966139458,0.008499999999999999
0.00085,198.4,101044.31129185455,0.008499999999999999
0.00085,197.8,100738.73373754452,0.008499999999999999
0.00085,197.4,100535.01536800449,0.008499999999999999
0.00086,197.0,100331.29699846444,0.0086
0.00086,196.4,100025.71944415441,0.0086
0.00086,196.1,99872.93066699938,0.0086
0.00086,195.6,99618.28270507435,0.0086
0.00086,195.3,99465.49392791933,0.0086
0.00087,194.8,99210.84596599429,0.0087
0.00087,194.3,98956.19800406926,0.0087
0.00087,193.7,98650.6204497592,0.0087
0.00087,193.2,98395.97248783417,0.0087
0.00087,192.7,98141.32452590913,0.0087
0.00087,192.2,97886.67656398409,0.0087
0.00087,191.8,97682.95819444407,0.0087
0.00087,191.3,97428.31023251904,0.0087
0.00088,190.8,97173.662270594,0.0088
0.00088,190.4,96969.94390105396,0.0088
0.00088,190.1,96817.15512389895,0.0088
0.00088,189.7,96613.4367543589,0.0088
0.00088,189.1,96307.85920004887,0.0088
0.0008900000000000001,188.5,96002.28164573883,0.0089
0.0008900000000000001,188.0,95747.6336838138,0.0089
0.0008900000000000001,187.4,95442.05612950375,0.0089
0.0008900000000000001,186.9,95187.40816757872,0.0089
0.0008900000000000001,186.3,94881.83061326867,0.0089
0.0008900000000000001,185.6,94525.32346657361,0.0089
0.0008900000000000001,185.1,94270.67550464858,0.0089
0.0009,183.9,93659.5203960285,0.009
0.0009,183.5,93455.80202648845,0.009
0.0009,183.1,93252.08365694842,0.009
0.0009,182.7,93048.3652874084,0.009
0.0009,182.2,92793.71732548336,0.009
0.00091,181.8,92589.99895594335,0.009099999999999999
0.00091,181.4,92386.28058640331,0.009099999999999999
0.00091,181.0,92182.56221686328,0.009099999999999999
0.00091,180.5,91927.91425493824,0.009099999999999999
0.00091,179.9,91622.3367006282,0.009099999999999999
0.00091,179.5,91418.61833108816,0.009099999999999999
0.00091,179.1,91214.89996154813,0.009099999999999999
0.00091,178.7,91011.1815920081,0.009099999999999999
0.00092,178.2,90756.53363008307,0.0092
0.00092,177.9,90603.74485292805,0.0092
0.00092,177.4,90349.09689100302,0.0092
0.00092,177.0,90145.37852146299,0.0092
0.00092,176.5,89890.73055953794,0.0092
0.00092,175.9,89585.15300522791,0.0092
0.00093,175.4,89330.50504330287,0.0093
0.00093,174.8,89024.92748899283,0.0093
0.00093,174.3,88770.27952706779,0.0093
0.00093,173.9,88566.56115752776,0.0093
0.00093,173.5,88362.84278798773,0.0093
0.00094,172.9,88057.26523367768,0.009399999999999999
0.00094,172.5,87853.54686413765,0.009399999999999999
0.00094,171.8,87497.0397174426,0.009399999999999999
0.00094,171.4,87293.32134790257,0.009399999999999999
0.00094,170.8,86987.74379359254,0.009399999999999999
0.00094,170.3,86733.0958316675,0.009399999999999999
0.00094,169.8,86478.44786974246,0.009399999999999999
0.00095,169.4,86274.72950020243,0.0095
0.00095,168.7,85918.22235350737,0.0095
0.00095,168.1,85612.64479919733,0.0095
0.00095,167.7,85408.9264296573,0.0095
0.00095,167.2,85154.27846773226,0.0095
0.00095,166.7,84899.63050580722,0.0095
0.00095,166.3,84695.9121362672,0.0095
0.0009599999999999999,165.8,84441.26417434217,0.0096
0.0009599999999999999,165.3,84186.61621241712,0.0096
0.0009599999999999999,164.9,83982.8978428771,0.0096
0.0009599999999999999,164.5,83779.17947333706,0.0096
0.0009599999999999999,164.1,83575.46110379703,0.0096
0.0009699999999999999,163.5,83269.883549487,0.009699999999999999
0.0009699999999999999,163.0,83015.23558756195,0.009699999999999999
0.0009699999999999999,162.7,82862.44681040692,0.009699999999999999
0.0009699999999999999,162.3,82658.72844086691,0.009699999999999999
0.0009699999999999999,161.8,82404.08047894188,0.009699999999999999
0.0009699999999999999,161.3,82149.43251701684,0.009699999999999999
0.0009699999999999999,160.8,81894.7845550918,0.009699999999999999
0.00098,160.4,81691.06618555177,0.0098
0.00098,160.0,81487.34781601174,0.0098
0.00098,159.7,81334.5590388567,0.0098
0.00098,159.4,81181.77026170169,0.0098
0.00098,159.0,80978.05189216166,0.0098
0.00098,158.6,80774.33352262163,0.0098
0.00098,158.0,80468.75596831158,0.0098
0.00099,157.5,80214.10800638655,0.009899999999999999
0.00099,157.1,80010.38963684652,0.009899999999999999
0.00099,156.7,79806.67126730649,0.009899999999999999
0.00099,156.3,79602.95289776647,0.009899999999999999
0.00099,155.8,79348.30493584143,0.009899999999999999
0.00099,155.2,79042.72738153138,0.009899999999999999
0.00099,154.7,78788.07941960634,0.009899999999999999
0.001,154.2,78533.4314576813,0.01
0.001,153.8,78329.71308814129,0.01
0.001,153.3,78075.06512621626,0.01
0.001,152.9,77871.34675667621,0.01
0.001,152.4,77616.69879475118,0.01
0.001,151.9,77362.05083282615,0.01
0.00101,151.4,77107.4028709011,0.0101
0.00101,151.1,76954.61409374609,0.0101
0.00101,150.7,76750.89572420604,0.0101
0.00101,150.4,76598.10694705104,0.0101
0.00101,150.0,76394.38857751101,0.0101
0.00101,149.4,76088.81102320096,0.0101
0.00101,149.0,75885.09265366093,0.0101
0.00101,148.7,75732.3038765059,0.0101
0.00101,148.4,75579.51509935089,0.0101
0.00102,148.1,75426.72632219586,0.0102
0.00102,147.8,75273.93754504084,0.0102
0.00102,147.4,75070.21917550081,0.0102
0.00102,146.9,74815.57121357578,0.0102
0.00102,146.6,74662.78243642075,0.0102
0.00103,146.2,74459.06406688072,0.0103
0.00103,145.6,74153.48651257067,0.0103
0.00103,145.2,73949.76814303064,0.0103
0.00103,144.8,73746.04977349062,0.0103
0.00103,144.4,73542.3314039506,0.0103
0.00103,143.8,73236.75384964056,0.0103
0.00103,143.3,72982.10588771552,0.0103
0.00103,143.0,72829.31711056049,0.0103
0.0010400000000000001,142.6,72625.59874102045,0.010400000000000001
0.0010400000000000001,142.2,72421.88037148042,0.010400000000000001
0.0010400000000000001,141.8,72218.1620019404,0.010400000000000001
0.0010400000000000001,141.2,71912.58444763035,0.010400000000000001
0.0010400000000000001,140.9,71759.79567047535,0.010400000000000001
0.0010400000000000001,140.4,71505.1477085503,0.010400000000000001
0.0010500000000000002,140.0,71301.42933901027,0.0105
0.0010500000000000002,139.7,71148.64056185524,0.0105
0.0010500000000000002,139.3,70944.92219231522,0.0105
0.0010500000000000002,138.9,70741.20382277519,0.0105
0.0010500000000000002,138.3,70435.62626846514,0.0105
0.0010500000000000002,137.9,70231.90789892511,0.0105
0.0010500000000000002,137.5,70028.18952938508,0.0105
0.00106,137.2,69875.40075223005,0.010599999999999998
0.00106,136.9,69722.61197507505,0.010599999999999998
0.00106,136.6,69569.82319792002,0.010599999999999998
0.00106,136.1,69315.17523599498,0.010599999999999998
0.00106,135.6,69060.52727406994,0.010599999999999998
0.00107,135.1,68805.87931214491,0.0107
0.00107,134.6,68551.23135021987,0.0107
0.00107,134.3,68398.44257306485,0.0107
0.00107,134.0,68245.65379590984,0.0107
0.00107,133.7,68092.8650187548,0.0107
0.00107,133.3,67889.14664921479,0.0107
0.00107,132.8,67634.49868728974,0.0107
0.00108,132.4,67430.78031774971,0.010799999999999999
0.00108,131.9,67176.13235582468,0.010799999999999999
0.00108,131.6,67023.34357866965,0.010799999999999999
0.00108,131.1,66768.69561674462,0.010799999999999999
0.00108,130.6,66514.04765481957,0.010799999999999999
0.00108,130.0,66208.47010050954,0.010799999999999999
0.00108,129.6,66004.75173096951,0.010799999999999999
0.00109,129.0,65699.17417665946,0.0109
0.00109,128.5,65444.526214734426,0.0109
0.00109,128.1,65240.807845194395,0.0109
0.00109,127.7,65037.08947565437,0.0109
0.00109,127.2,64782.44151372933,0.0109
0.00109,126.8,64578.7231441893,0.0109
0.0011,126.3,64324.07518226426,0.011
0.0011,125.9,64120.35681272424,0.011
0.0011,125.5,63916.63844318421,0.011
0.0011,125.1,63712.92007364417,0.011
0.0011,124.5,63407.34251933413,0.011
0.0011,124.1,63203.6241497941,0.011
0.0011,123.6,62948.97618786906,0.011
0.00111,123.1,62694.328225944024,0.0111
0.00111,122.7,62490.609856404,0.0111
0.00111,122.3,62286.89148686397,0.0111
0.00111,121.8,62032.24352493893,0.0111
0.00111,121.3,61777.5955630139,0.0111
0.00111,120.8,61522.94760108886,0.0111
0.00111,120.4,61319.22923154884,0.0111
0.00111,120.0,61115.5108620088,0.0111
0.00111,119.7,60962.72208485378,0.0111
0.00111,119.2,60708.074122928745,0.0111
0.0011200000000000001,118.9,60555.28534577372,0.0112
0.0011200000000000001,118.6,60402.4965686187,0.0112
0.0011200000000000001,118.3,60249.707791463676,0.0112
0.0011200000000000001,118.0,60096.91901430865,0.0112
0.0011200000000000001,117.6,59893.20064476862,0.0112
0.0011200000000000001,117.2,59689.4822752286,0.0112
0.00113,116.9,59536.693498073575,0.0113
0.00113,116.5,59332.975128533544,0.0113
0.00113,116.2,59180.18635137853,0.0113
0.00113,115.9,59027.397574223505,0.0113
0.00113,115.6,58874.608797068475,0.0113
0.00113,115.3,58721.82001991346,0.0113
0.00113,115.0,58569.031242758436,0.0113
0.00114,114.7,58416.24246560341,0.011399999999999999
0.00114,114.4,58263.4536884484,0.011399999999999999
0.00114,114.1,58110.66491129337,0.011399999999999999
0.00114,113.6,57856.01694936833,0.011399999999999999
0.00114,113.2,57652.298579828304,0.011399999999999999
0.00114,112.9,57499.50980267328,0.011399999999999999
0.00115,112.6,57346.72102551826,0.0115
0.00115,112.3,57193.932248363235,0.0115
0.00115,111.9,56990.21387882321,0.0115
0.00115,111.5,56786.49550928318,0.0115
0.00115,111.1,56582.77713974315,0.0115
0.00115,110.7,56379.05877020312,0.0115
0.00116,110.3,56175.34040066309,0.0116